Workbook

Sheet Instructions
B2: SDLC Risk & Control Self-Assessment
B3: Aligned to the Kosli Secure SDLC model: 9 risks, 22 controls (Build · Release · Runtime · Lifecycle) and the risk↔control mapping
B5: Organization / Product | C5: [ enter ]
B6: In-scope services / systems | C6: [ enter ]
B7: Assessment period | C7: [ enter ]
B8: Risk owner / Assessor | C8: [ enter ]
B9: Date prepared | C9: [ enter ]
B10: Next review due | C10: [ enter ]
B11: Version | C11: 2
B13: How this template works
B14: Model | C14: This template separates RISKS from CONTROLS and connects them in a matrix. Controls are grouped as Build, Release, Runtime and Lifecycle. Residual risk is not entered manually — each risk's residual Likelihood and Impact are driven automatically by the average effectiveness of its mapped controls (see the Methodology tab).
B15: 1. Risk Register | C15: Assess each of the 9 SDLC risks: rate inherent Likelihood & Impact (no controls), then rate the effectiveness of the mapped controls on the Control sheets. Residual risk is calculated automatically from that effectiveness. Assign a risk owner and, where needed, an action plan.
B16: 2. Risk-Control Matrix | C16: Shows which controls mitigate which risks — exactly as defined in the model. 'X' marks a mapped relationship. Row and column totals calculate automatically.
B17: 3. Control sheets | C17: One tab per control group (Build / Release / Runtime / Lifecycle). For each control record its implementation status, effectiveness, owner, evidence and any remediation. 'Risks mitigated' lists the risks each control addresses.
B18: 4. Dashboard | C18: Aggregates residual risk ratings, control implementation status and coverage.
B19: Reference | C19: The 'Scoring Legend' tab defines the 1–5 scales, heat map and control-effectiveness weights; 'Definitions' explains every column and value; 'Model Reference' lists all risks and controls; 'Methodology' documents the full approach.
B21: Notes
B22: • | C22: Blue text = inputs you complete. Black text = automatic calculations — do not overwrite.
B23: • | C23: Risks, controls and the risk↔control mappings reproduce a secure-SDLC reference model (see Model Reference). Inherent ratings and control effectiveness are illustrative samples — reassess for your organization; residual scores then calculate automatically.
B24: • | C24: The reference model is a living template; verify control and risk definitions against the current source, and tailor ownership, evidence and scoring to your environment.
C27: This SDLC template is reference from the Kosli

Sheet Dashboard
B2: RCSA Summary Dashboard
B4: Total risks | C4: =COUNTA('Risk Register'!A4:A12) -> 9 | E4: Total controls | F4: =COUNTA('Build Controls'!A4:A100)+COUNTA('Release Controls'!A4:A100)+COUNTA('Runtime Controls'!A4:A100)+COUNTA('Lifecycle Controls'!A4:A100) -> 29 | I4: Effective | J4: Partially Effective | K4: Ineffective | L4: Not Tested
I5: {=IFERROR(_xlfn._xlws.FILTER(_xlfn.VSTACK('Build Controls'!A4:A9,'Release Controls'!A4:A10,'Runtime Controls'!A4:A9,'Lifecycle Controls'!A4:A6),_xlfn.VSTACK('Build Controls'!I4:I9,'Release Controls'!I4:I10,'Runtime Controls'!I4:I9,'Lifecycle Controls'!I4:I6)=I$4,"—"),"—")} -> CTRL-0007 | J5: {=IFERROR(_xlfn._xlws.FILTER(_xlfn.VSTACK('Build Controls'!A4:A9,'Release Controls'!A4:A10,'Runtime Controls'!A4:A9,'Lifecycle Controls'!A4:A6),_xlfn.VSTACK('Build Controls'!I4:I9,'Release Controls'!I4:I10,'Runtime Controls'!I4:I9,'Lifecycle Controls'!I4:I6)=J$4,"—"),"—")} -> — | K5: {=IFERROR(_xlfn._xlws.FILTER(_xlfn.VSTACK('Build Controls'!A4:A9,'Release Controls'!A4:A10,'Runtime Controls'!A4:A9,'Lifecycle Controls'!A4:A6),_xlfn.VSTACK('Build Controls'!I4:I9,'Release Controls'!I4:I10,'Runtime Controls'!I4:I9,'Lifecycle Controls'!I4:I6)=K$4,"—"),"—")} -> CTRL-0001 | L5: {=IFERROR(_xlfn._xlws.FILTER(_xlfn.VSTACK('Build Controls'!A4:A9,'Release Controls'!A4:A10,'Runtime Controls'!A4:A9,'Lifecycle Controls'!A4:A6),_xlfn.VSTACK('Build Controls'!I4:I9,'Release Controls'!I4:I10,'Runtime Controls'!I4:I9,'Lifecycle Controls'!I4:I6)=L$4,"—"),"—")} -> CTRL-0005
B6: Residual risk by rating | C6: Count | E6: Inherent risk by rating | F6: Count | I6: CTRL-0019 | K6: CTRL-0002 | L6: CTRL-0008
B7: Critical | C7: =COUNTIF('Risk Register'!$N$4:$N$12,"Critical") -> 5 | E7: Critical | F7: =COUNTIF('Risk Register'!$I$4:$I$12,"Critical") -> 6 | K7: CTRL-0003 | L7: CTRL-0010
B8: High | C8: =COUNTIF('Risk Register'!$N$4:$N$12,"High") -> 3 | E8: High | F8: =COUNTIF('Risk Register'!$I$4:$I$12,"High") -> 3 | K8: CTRL-0004 | L8: CTRL-0023
B9: Medium | C9: =COUNTIF('Risk Register'!$N$4:$N$12,"Medium") -> 1 | E9: Medium | F9: =COUNTIF('Risk Register'!$I$4:$I$12,"Medium") -> 0 | K9: CTRL-0006 | L9: CTRL-0012
B10: Low | C10: =COUNTIF('Risk Register'!$N$4:$N$12,"Low") -> 0 | E10: Low | F10: =COUNTIF('Risk Register'!$I$4:$I$12,"Low") -> 0 | K10: CTRL-0020 | L10: CTRL-0018
K11: CTRL-0021 | L11: CTRL-0017
B12: Control implementation status | C12: Count | E12: Controls by group | F12: Count | K12: CTRL-0022 | L12: CTRL-0011
B13: Implemented | C13: =COUNTIF('Build Controls'!$H$4:$H$100,"Implemented")+COUNTIF('Release Controls'!$H$4:$H$100,"Implemented")+COUNTIF('Runtime Controls'!$H$4:$H$100,"Implemented")+COUNTIF('Lifecycle Controls'!$H$4:$H$100,"Implemented") -> 7 | E13: Build Controls | F13: =COUNTA('Build Controls'!A4:A100) -> 9 | K13: CTRL-0013
B14: Partially Implemented | C14: =COUNTIF('Build Controls'!$H$4:$H$100,"Partially Implemented")+COUNTIF('Release Controls'!$H$4:$H$100,"Partially Implemented")+COUNTIF('Runtime Controls'!$H$4:$H$100,"Partially Implemented")+COUNTIF('Lifecycle Controls'!$H$4:$H$100,"Partially Implemented") -> 1 | E14: Release Controls | F14: =COUNTA('Release Controls'!A4:A100) -> 8 | K14: CTRL-0014
B15: Planned | C15: =COUNTIF('Build Controls'!$H$4:$H$100,"Planned")+COUNTIF('Release Controls'!$H$4:$H$100,"Planned")+COUNTIF('Runtime Controls'!$H$4:$H$100,"Planned")+COUNTIF('Lifecycle Controls'!$H$4:$H$100,"Planned") -> 1 | E15: Runtime Controls | F15: =COUNTA('Runtime Controls'!A4:A100) -> 7 | K15: CTRL-0015
B16: Not Implemented | C16: =COUNTIF('Build Controls'!$H$4:$H$100,"Not Implemented")+COUNTIF('Release Controls'!$H$4:$H$100,"Not Implemented")+COUNTIF('Runtime Controls'!$H$4:$H$100,"Not Implemented")+COUNTIF('Lifecycle Controls'!$H$4:$H$100,"Not Implemented") -> 20 | E16: Lifecycle Controls | F16: =COUNTA('Lifecycle Controls'!A4:A100) -> 5 | K16: CTRL-0016
B18: Control effectiveness | C18: Count
B19: Effective | C19: =COUNTIF('Build Controls'!$I$4:$I$100,$B19)+COUNTIF('Release Controls'!$I$4:$I$100,$B19)+COUNTIF('Runtime Controls'!$I$4:$I$100,$B19)+COUNTIF('Lifecycle Controls'!$I$4:$I$100,$B19) -> 3
B20: Partially Effective | C20: =COUNTIF('Build Controls'!$I$4:$I$100,$B20)+COUNTIF('Release Controls'!$I$4:$I$100,$B20)+COUNTIF('Runtime Controls'!$I$4:$I$100,$B20)+COUNTIF('Lifecycle Controls'!$I$4:$I$100,$B20) -> 2
B21: Ineffective | C21: =COUNTIF('Build Controls'!$I$4:$I$100,$B21)+COUNTIF('Release Controls'!$I$4:$I$100,$B21)+COUNTIF('Runtime Controls'!$I$4:$I$100,$B21)+COUNTIF('Lifecycle Controls'!$I$4:$I$100,$B21) -> 16
B22: Not Tested | C22: =COUNTIF('Build Controls'!$I$4:$I$100,$B22)+COUNTIF('Release Controls'!$I$4:$I$100,$B22)+COUNTIF('Runtime Controls'!$I$4:$I$100,$B22)+COUNTIF('Lifecycle Controls'!$I$4:$I$100,$B22) -> 8

Sheet Risk Register
A1: Risk Register — SDLC Risks (RISK-0001 … 0009)
A2: RISK | F2: INHERENT RISK | J2: EFFECT. | K2: RESIDUAL RISK | O2: RESPONSE & OWNER | U2: CONTROL-DRIVEN
A3: Risk ID | B3: Risk | C3: Description | D3: Mapped Control IDs | E3: # Ctrls | F3: Inh. L | G3: Inh. I | H3: Inh. Score | I3: Inh. Rating | J3: Control Effectiveness | K3: Res. L | L3: Res. I | M3: Res. Score | N3: Res. Rating | O3: Risk Response | P3: Risk Owner | Q3: Action Plan | R3: Action Owner | S3: Target Date | T3: Status | U3: Avg Ctrl Eff
A4: RISK-0001 | B4: Supply Chain Compromise | C4: Malicious or tampered components (open-source libraries, base images, build tools, third-party services) enter the SDLC, resulting in compromised applications reaching production. | D4: 0002, 0003, 0004, 0013, 0016, 0020, 0021, 0022, 0024, 0025 | E4: =COUNTIF('Risk-Control Matrix'!C4:AE4,"X") -> 10 | F4: 4 | G4: 5 | H4: =F4*G4 -> 20 | I4: =IF(H4="","",IF(H4>=15,"Critical",IF(H4>=8,"High",IF(H4>=4,"Medium","Low")))) -> Critical | J4: Effective | K4: =ROUND(F4-(F4-1)*$U4,0) -> 4 | L4: =ROUND(G4-(G4-1)*$U4,0) -> 5 | M4: =K4*L4 -> 20 | N4: =IF(M4="","",IF(M4>=15,"Critical",IF(M4>=8,"High",IF(M4>=4,"Medium","Low")))) -> Critical | O4: Mitigate | T4: Implemented | U4: {=IFERROR(SUMPRODUCT(('Risk-Control Matrix'!C4:AE4="X")*'Risk-Control Matrix'!$C$18:$AE$18)/COUNTIF('Risk-Control Matrix'!C4:AE4,"X"),0)} -> 0
A5: RISK-0002 | B5: Insider Threat | C5: Authorised personnel (or attackers using their credentials) misuse legitimate access to repositories, environments or production to compromise confidentiality, integrity or availability. | D5: 0001, 0007, 0010, 0012, 0013, 0014, 0015, 0016, 0017 | E5: =COUNTIF('Risk-Control Matrix'!C5:AE5,"X") -> 9 | F5: 3 | G5: 5 | H5: =F5*G5 -> 15 | I5: =IF(H5="","",IF(H5>=15,"Critical",IF(H5>=8,"High",IF(H5>=4,"Medium","Low")))) -> Critical | J5: Not Tested | K5: =ROUND(F5-(F5-1)*$U5,0) -> 3 | L5: =ROUND(G5-(G5-1)*$U5,0) -> 5 | M5: =K5*L5 -> 15 | N5: =IF(M5="","",IF(M5>=15,"Critical",IF(M5>=8,"High",IF(M5>=4,"Medium","Low")))) -> Critical | O5: Mitigate | T5: In Progress | U5: {=IFERROR(SUMPRODUCT(('Risk-Control Matrix'!C5:AE5="X")*'Risk-Control Matrix'!$C$18:$AE$18)/COUNTIF('Risk-Control Matrix'!C5:AE5,"X"),0)} -> 0.11111111
A6: RISK-0003 | B6: Unauthorised Deployment | C6: Software is deployed to production without passing required quality gates, security scans or approval checks. | D6: 0002, 0010, 0013, 0016 | E6: =COUNTIF('Risk-Control Matrix'!C6:AE6,"X") -> 4 | F6: 3 | G6: 4 | H6: =F6*G6 -> 12 | I6: =IF(H6="","",IF(H6>=15,"Critical",IF(H6>=8,"High",IF(H6>=4,"Medium","Low")))) -> High | J6: Not Tested | K6: =ROUND(F6-(F6-1)*$U6,0) -> 3 | L6: =ROUND(G6-(G6-1)*$U6,0) -> 4 | M6: =K6*L6 -> 12 | N6: =IF(M6="","",IF(M6>=15,"Critical",IF(M6>=8,"High",IF(M6>=4,"Medium","Low")))) -> High | O6: Mitigate | T6: In Progress | U6: {=IFERROR(SUMPRODUCT(('Risk-Control Matrix'!C6:AE6="X")*'Risk-Control Matrix'!$C$18:$AE$18)/COUNTIF('Risk-Control Matrix'!C6:AE6,"X"),0)} -> 0
A7: RISK-0004 | B7: Credential and Secret Exposure | C7: Leaked or poorly managed secrets enable unauthorised access to production systems, customer data or pipelines. | D7: 0001, 0006, 0014, 0015, 0027 | E7: =COUNTIF('Risk-Control Matrix'!C7:AE7,"X") -> 5 | F7: 4 | G7: 5 | H7: =F7*G7 -> 20 | I7: =IF(H7="","",IF(H7>=15,"Critical",IF(H7>=8,"High",IF(H7>=4,"Medium","Low")))) -> Critical | J7: Not Tested | K7: =ROUND(F7-(F7-1)*$U7,0) -> 4 | L7: =ROUND(G7-(G7-1)*$U7,0) -> 5 | M7: =K7*L7 -> 20 | N7: =IF(M7="","",IF(M7>=15,"Critical",IF(M7>=8,"High",IF(M7>=4,"Medium","Low")))) -> Critical | O7: Mitigate | T7: In Progress | U7: {=IFERROR(SUMPRODUCT(('Risk-Control Matrix'!C7:AE7="X")*'Risk-Control Matrix'!$C$18:$AE$18)/COUNTIF('Risk-Control Matrix'!C7:AE7,"X"),0)} -> 0
A8: RISK-0005 | B8: Vulnerable Software in Production | C8: Known vulnerabilities in code or dependencies are exploited in the production environment. | D8: 0004, 0008, 0016, 0019, 0020, 0021, 0022, 0024, 0045, 0026 | E8: =COUNTIF('Risk-Control Matrix'!C8:AE8,"X") -> 10 | F8: 4 | G8: 4 | H8: =F8*G8 -> 16 | I8: =IF(H8="","",IF(H8>=15,"Critical",IF(H8>=8,"High",IF(H8>=4,"Medium","Low")))) -> Critical | J8: Not Tested | K8: =ROUND(F8-(F8-1)*$U8,0) -> 4 | L8: =ROUND(G8-(G8-1)*$U8,0) -> 4 | M8: =K8*L8 -> 16 | N8: =IF(M8="","",IF(M8>=15,"Critical",IF(M8>=8,"High",IF(M8>=4,"Medium","Low")))) -> Critical | O8: Mitigate | T8: In Progress | U8: {=IFERROR(SUMPRODUCT(('Risk-Control Matrix'!C8:AE8="X")*'Risk-Control Matrix'!$C$18:$AE$18)/COUNTIF('Risk-Control Matrix'!C8:AE8,"X"),0)} -> 0.1
A9: RISK-0006 | B9: Audit and Compliance Failure | C9: Inability to evidence controls to regulators, auditors or enterprise customers, resulting in reputational or commercial damage. | D9: 0002, 0007, 0010, 0012, 0015, 0016, 0028, 0029 | E9: =COUNTIF('Risk-Control Matrix'!C9:AE9,"X") -> 8 | F9: 3 | G9: 4 | H9: =F9*G9 -> 12 | I9: =IF(H9="","",IF(H9>=15,"Critical",IF(H9>=8,"High",IF(H9>=4,"Medium","Low")))) -> High | J9: Not Tested | K9: =ROUND(F9-(F9-1)*$U9,0) -> 2 | L9: =ROUND(G9-(G9-1)*$U9,0) -> 3 | M9: =K9*L9 -> 6 | N9: =IF(M9="","",IF(M9>=15,"Critical",IF(M9>=8,"High",IF(M9>=4,"Medium","Low")))) -> Medium | O9: Mitigate | T9: In Progress | U9: {=IFERROR(SUMPRODUCT(('Risk-Control Matrix'!C9:AE9="X")*'Risk-Control Matrix'!$C$18:$AE$18)/COUNTIF('Risk-Control Matrix'!C9:AE9,"X"),0)} -> 0.3125
A10: RISK-0007 | B10: Unauthorised System Access | C10: Production environments are accessed by personnel without appropriate authorisation or full audit trails. | D10: 0014, 0015 | E10: =COUNTIF('Risk-Control Matrix'!C10:AE10,"X") -> 2 | F10: 3 | G10: 5 | H10: =F10*G10 -> 15 | I10: =IF(H10="","",IF(H10>=15,"Critical",IF(H10>=8,"High",IF(H10>=4,"Medium","Low")))) -> Critical | J10: Not Tested | K10: =ROUND(F10-(F10-1)*$U10,0) -> 3 | L10: =ROUND(G10-(G10-1)*$U10,0) -> 5 | M10: =K10*L10 -> 15 | N10: =IF(M10="","",IF(M10>=15,"Critical",IF(M10>=8,"High",IF(M10>=4,"Medium","Low")))) -> Critical | O10: Mitigate | T10: In Progress | U10: {=IFERROR(SUMPRODUCT(('Risk-Control Matrix'!C10:AE10="X")*'Risk-Control Matrix'!$C$18:$AE$18)/COUNTIF('Risk-Control Matrix'!C10:AE10,"X"),0)} -> 0
A11: RISK-0008 | B11: Configuration Drift | C11: Infrastructure or application configuration diverges from its known, approved state, causing undetected changes in security posture or behaviour. | D11: 0001, 0005, 0012, 0013, 0018 | E11: =COUNTIF('Risk-Control Matrix'!C11:AE11,"X") -> 5 | F11: 4 | G11: 3 | H11: =F11*G11 -> 12 | I11: =IF(H11="","",IF(H11>=15,"Critical",IF(H11>=8,"High",IF(H11>=4,"Medium","Low")))) -> High | J11: Not Tested | K11: =ROUND(F11-(F11-1)*$U11,0) -> 4 | L11: =ROUND(G11-(G11-1)*$U11,0) -> 3 | M11: =K11*L11 -> 12 | N11: =IF(M11="","",IF(M11>=15,"Critical",IF(M11>=8,"High",IF(M11>=4,"Medium","Low")))) -> High | O11: Mitigate | T11: In Progress | U11: {=IFERROR(SUMPRODUCT(('Risk-Control Matrix'!C11:AE11="X")*'Risk-Control Matrix'!$C$18:$AE$18)/COUNTIF('Risk-Control Matrix'!C11:AE11,"X"),0)} -> 0
A12: RISK-0009 | B12: Environment Breach | C12: An external attacker runs unauthorised workloads within the production environment. | D12: 0015, 0016, 0019 | E12: =COUNTIF('Risk-Control Matrix'!C12:AE12,"X") -> 3 | F12: 3 | G12: 5 | H12: =F12*G12 -> 15 | I12: =IF(H12="","",IF(H12>=15,"Critical",IF(H12>=8,"High",IF(H12>=4,"Medium","Low")))) -> Critical | J12: Not Tested | K12: =ROUND(F12-(F12-1)*$U12,0) -> 2 | L12: =ROUND(G12-(G12-1)*$U12,0) -> 4 | M12: =K12*L12 -> 8 | N12: =IF(M12="","",IF(M12>=15,"Critical",IF(M12>=8,"High",IF(M12>=4,"Medium","Low")))) -> High | O12: Mitigate | T12: In Progress | U12: {=IFERROR(SUMPRODUCT(('Risk-Control Matrix'!C12:AE12="X")*'Risk-Control Matrix'!$C$18:$AE$18)/COUNTIF('Risk-Control Matrix'!C12:AE12,"X"),0)} -> 0.33333333
A13: RISK-0010 | B13: GenAI & Code Assistant Exploitation | C13: Developers using unvetted public LLMs or autonomous AI coding agents introduce package hallucinations, unauthorized license liabilities, or inadvertently leak proprietary source code/secrets into public models. | D13: 0007, 0029 | E13: =COUNTIF('Risk-Control Matrix'!C13:AE13,"X") -> 2 | F13: 4 | G13: 4 | H13: =F13*G13 -> 16 | I13: =IF(H13="","",IF(H13>=15,"Critical",IF(H13>=8,"High",IF(H13>=4,"Medium","Low")))) -> Critical | J13: Not Tested | K13: =ROUND(F13-(F13-1)*$U13,0) -> 2 | L13: =ROUND(G13-(G13-1)*$U13,0) -> 2 | M13: =K13*L13 -> 4 | N13: =IF(M13="","",IF(M13>=15,"Critical",IF(M13>=8,"High",IF(M13>=4,"Medium","Low")))) -> Medium | O13: Mitigate | T13: In Progress | U13: {=IFERROR(SUMPRODUCT(('Risk-Control Matrix'!C13:AE13="X")*'Risk-Control Matrix'!$C$18:$AE$18)/COUNTIF('Risk-Control Matrix'!C13:AE13,"X"),0)} -> 0.75
A14: RISK-0011 | B14: Insecure Infrastructure as Code (IaC) | C14: Cloud deployment configurations, container orchestration manifest files (Terraform, Helm charts, Kubernetes YAML), or environment parameters contain systemic access-control vulnerabilities or overly permissive IAM footprints committed directly into the code. | D14: 0005, 0026 | E14: =COUNTIF('Risk-Control Matrix'!C14:AE14,"X") -> 2 | F14: 4 | G14: 4 | H14: =F14*G14 -> 16 | I14: =IF(H14="","",IF(H14>=15,"Critical",IF(H14>=8,"High",IF(H14>=4,"Medium","Low")))) -> Critical | J14: Not Tested | K14: =ROUND(F14-(F14-1)*$U14,0) -> 4 | L14: =ROUND(G14-(G14-1)*$U14,0) -> 4 | M14: =K14*L14 -> 16 | N14: =IF(M14="","",IF(M14>=15,"Critical",IF(M14>=8,"High",IF(M14>=4,"Medium","Low")))) -> Critical | O14: Mitigate | T14: In Progress | U14: {=IFERROR(SUMPRODUCT(('Risk-Control Matrix'!C14:AE14="X")*'Risk-Control Matrix'!$C$18:$AE$18)/COUNTIF('Risk-Control Matrix'!C14:AE14,"X"),0)} -> 0
A15: RISK-0012 | B15: Insecure Architectural Design | C15: Core functional flaws in application logic, business processing flows, data tenancy boundaries, or upstream API design contracts are introduced during early product specification phases, passing downstream syntactical pipeline scans undetected. | D15: 0028, 0030 | E15: =COUNTIF('Risk-Control Matrix'!C15:AE15,"X") -> 2 | F15: 3 | G15: 5 | H15: =F15*G15 -> 15 | I15: =IF(H15="","",IF(H15>=15,"Critical",IF(H15>=8,"High",IF(H15>=4,"Medium","Low")))) -> Critical | J15: Not Tested | K15: =ROUND(F15-(F15-1)*$U15,0) -> 2 | L15: =ROUND(G15-(G15-1)*$U15,0) -> 2 | M15: =K15*L15 -> 4 | N15: =IF(M15="","",IF(M15>=15,"Critical",IF(M15>=8,"High",IF(M15>=4,"Medium","Low")))) -> Medium | O15: Mitigate | T15: In Progress | U15: {=IFERROR(SUMPRODUCT(('Risk-Control Matrix'!C15:AE15="X")*'Risk-Control Matrix'!$C$18:$AE$18)/COUNTIF('Risk-Control Matrix'!C15:AE15,"X"),0)} -> 0.75

Sheet Risk-Control Matrix
A1: Risk-Control Matrix — which controls mitigate which risks
C2: BUILD | L2: RELEASE | T2: RUNTIME | AA2: LIFECYCLE
A3: Risk ID | B3: Risk | C3: 0001 | D3: 0002 | E3: 0003 | F3: 0004 | G3: 0005 | H3: 0006 | I3: 0024 | J3: 0025 | K3: 0026 | L3: 0007 | M3: 0008 | N3: 0020 | O3: 0021 | P3: 0022 | Q3: 0010 | R3: 0023 | S3: 0030 | T3: 0012 | U3: 0013 | V3: 0014 | W3: 0015 | X3: 0016 | Y3: 0018 | Z3: 0027 | AA3: 0017 | AB3: 0019 | AC3: 0011 | AD3: 0028 | AE3: 0029 | AF3: # Ctrls
A4: RISK-0001 | B4: Supply Chain Compromise | D4: X | E4: X | F4: X | I4: X | J4: X | N4: X | O4: X | P4: X | U4: X | X4: X | AF4: =COUNTIF(C4:AE4,"X") -> 10
A5: RISK-0002 | B5: Insider Threat | C5: X | L5: X | Q5: X | T5: X | U5: X | V5: X | W5: X | X5: X | AA5: X | AF5: =COUNTIF(C5:AE5,"X") -> 9
A6: RISK-0003 | B6: Unauthorised Deployment | D6: X | Q6: X | U6: X | X6: X | AF6: =COUNTIF(C6:AE6,"X") -> 4
A7: RISK-0004 | B7: Credential and Secret Exposure | C7: X | H7: X | V7: X | W7: X | Z7: X | AF7: =COUNTIF(C7:AE7,"X") -> 5
A8: RISK-0005 | B8: Vulnerable Software in Production | F8: X | I8: X | J8: X | K8: X | M8: X | N8: X | O8: X | P8: X | X8: X | AB8: X | AF8: =COUNTIF(C8:AE8,"X") -> 10
A9: RISK-0006 | B9: Audit and Compliance Failure | D9: X | L9: X | Q9: X | T9: X | W9: X | X9: X | AD9: X | AE9: X | AF9: =COUNTIF(C9:AE9,"X") -> 8
A10: RISK-0007 | B10: Unauthorised System Access | V10: X | W10: X | AF10: =COUNTIF(C10:AE10,"X") -> 2
A11: RISK-0008 | B11: Configuration Drift | C11: X | G11: X | T11: X | U11: X | Y11: X | AF11: =COUNTIF(C11:AE11,"X") -> 5
A12: RISK-0009 | B12: Environment Breach | W12: X | X12: X | AB12: X | AF12: =COUNTIF(C12:AE12,"X") -> 3
A13: RISK-0010 | B13: GenAI & Code Assistant Exploitation | L13: X | AE13: X | AF13: =COUNTIF(C13:AE13,"X") -> 2
A14: RISK-0011 | B14: Insecure Infrastructure as Code (IaC) | G14: X | K14: X | AF14: =COUNTIF(C14:AE14,"X") -> 2
A15: RISK-0012 | B15: Insecure Architectural Design | S15: X | AD15: X | AF15: =COUNTIF(C15:AE15,"X") -> 2
A16: # Risks | B16: (per control) | C16: =COUNTIF(C4:C15,"X") -> 3 | D16: =COUNTIF(D4:D15,"X") -> 3 | E16: =COUNTIF(E4:E15,"X") -> 1 | F16: =COUNTIF(F4:F15,"X") -> 2 | G16: =COUNTIF(G4:G15,"X") -> 2 | H16: =COUNTIF(H4:H15,"X") -> 1 | I16: =COUNTIF(I4:I15,"X") -> 2 | J16: =COUNTIF(J4:J15,"X") -> 2 | ... AE16: =COUNTIF(AE4:AE15,"X") -> 2 | AF16: =SUM(C16:AE16) -> 62
B17: Control Effectiveness (live) | C17: =IFERROR(VLOOKUP("CTRL-"&C$3,'Build Controls'!$A$4:$I$9,9,FALSE),IFERROR(VLOOKUP("CTRL-"&C$3,'Release Controls'!$A$4:$I$10,9,FALSE),IFERROR(VLOOKUP("CTRL-"&C$3,'Runtime Controls'!$A$4:$I$9,9,FALSE),IFERROR(VLOOKUP("CTRL-"&C$3,'Lifecycle Controls'!$A$4:$I$6,9,FALSE),"—")))) -> Ineffective | D17: =IFERROR(VLOOKUP("CTRL-"&D$3,'Build Controls'!$A$4:$I$9,9,FALSE),IFERROR(VLOOKUP("CTRL-"&D$3,'Release Controls'!$A$4:$I$10,9,FALSE),IFERROR(VLOOKUP("CTRL-"&D$3,'Runtime Controls'!$A$4:$I$9,9,FALSE),IFERROR(VLOOKUP("CTRL-"&D$3,'Lifecycle Controls'!$A$4:$I$6,9,FALSE),"—")))) -> Ineffective | E17: =IFERROR(VLOOKUP("CTRL-"&E$3,'Build Controls'!$A$4:$I$9,9,FALSE),IFERROR(VLOOKUP("CTRL-"&E$3,'Release Controls'!$A$4:$I$10,9,FALSE),IFERROR(VLOOKUP("CTRL-"&E$3,'Runtime Controls'!$A$4:$I$9,9,FALSE),IFERROR(VLOOKUP("CTRL-"&E$3,'Lifecycle Controls'!$A$4:$I$6,9,FALSE),"—")))) -> Ineffective | F17: =IFERROR(VLOOKUP("CTRL-"&F$3,'Build Controls'!$A$4:$I$9,9,FALSE),IFERROR(VLOOKUP("CTRL-"&F$3,'Release Controls'!$A$4:$I$10,9,FALSE),IFERROR(VLOOKUP("CTRL-"&F$3,'Runtime Controls'!$A$4:$I$9,9,FALSE),IFERROR(VLOOKUP("CTRL-"&F$3,'Lifecycle Controls'!$A$4:$I$6,9,FALSE),"—")))) -> Ineffective | G17: =IFERROR(VLOOKUP("CTRL-"&G$3,'Build Controls'!$A$4:$I$9,9,FALSE),IFERROR(VLOOKUP("CTRL-"&G$3,'Release Controls'!$A$4:$I$10,9,FALSE),IFERROR(VLOOKUP("CTRL-"&G$3,'Runtime Controls'!$A$4:$I$9,9,FALSE),IFERROR(VLOOKUP("CTRL-"&G$3,'Lifecycle Controls'!$A$4:$I$6,9,FALSE),"—")))) -> Not Tested | H17: =IFERROR(VLOOKUP("CTRL-"&H$3,'Build Controls'!$A$4:$I$9,9,FALSE),IFERROR(VLOOKUP("CTRL-"&H$3,'Release Controls'!$A$4:$I$10,9,FALSE),IFERROR(VLOOKUP("CTRL-"&H$3,'Runtime Controls'!$A$4:$I$9,9,FALSE),IFERROR(VLOOKUP("CTRL-"&H$3,'Lifecycle Controls'!$A$4:$I$6,9,FALSE),"—")))) -> Ineffective | I17: =IFERROR(VLOOKUP("CTRL-"&I$3,'Build Controls'!$A$4:$I$12,9,FALSE),IFERROR(VLOOKUP("CTRL-"&I$3,'Release Controls'!$A$4:$I$10,9,FALSE),IFERROR(VLOOKUP("CTRL-"&I$3,'Runtime Controls'!$A$4:$I$9,9,FALSE),IFERROR(VLOOKUP("CTRL-"&I$3,'Lifecycle Controls'!$A$4:$I$6,9,FALSE),"—")))) -> Ineffective | J17: =IFERROR(VLOOKUP("CTRL-"&J$3,'Build Controls'!$A$4:$I$12,9,FALSE),IFERROR(VLOOKUP("CTRL-"&J$3,'Release Controls'!$A$4:$I$10,9,FALSE),IFERROR(VLOOKUP("CTRL-"&J$3,'Runtime Controls'!$A$4:$I$9,9,FALSE),IFERROR(VLOOKUP("CTRL-"&J$3,'Lifecycle Controls'!$A$4:$I$6,9,FALSE),"—")))) -> Ineffective | K17: =IFERROR(VLOOKUP("CTRL-"&K$3,'Build Controls'!$A$4:$I$12,9,FALSE),IFERROR(VLOOKUP("CTRL-"&K$3,'Release Controls'!$A$4:$I$10,9,FALSE),IFERROR(VLOOKUP("CTRL-"&K$3,'Runtime Controls'!$A$4:$I$9,9,FALSE),IFERROR(VLOOKUP("CTRL-"&K$3,'Lifecycle Controls'!$A$4:$I$6,9,FALSE),"—")))) -> Ineffective | L17: =IFERROR(VLOOKUP("CTRL-"&L$3,'Build Controls'!$A$4:$I$9,9,FALSE),IFERROR(VLOOKUP("CTRL-"&L$3,'Release Controls'!$A$4:$I$10,9,FALSE),IFERROR(VLOOKUP("CTRL-"&L$3,'Runtime Controls'!$A$4:$I$9,9,FALSE),IFERROR(VLOOKUP("CTRL-"&L$3,'Lifecycle Controls'!$A$4:$I$6,9,FALSE),"—")))) -> Effective | M17: =IFERROR(VLOOKUP("CTRL-"&M$3,'Build Controls'!$A$4:$I$9,9,FALSE),IFERROR(VLOOKUP("CTRL-"&M$3,'Release Controls'!$A$4:$I$10,9,FALSE),IFERROR(VLOOKUP("CTRL-"&M$3,'Runtime Controls'!$A$4:$I$9,9,FALSE),IFERROR(VLOOKUP("CTRL-"&M$3,'Lifecycle Controls'!$A$4:$I$6,9,FALSE),"—")))) -> Not Tested | N17: =IFERROR(VLOOKUP("CTRL-"&N$3,'Build Controls'!$A$4:$I$9,9,FALSE),IFERROR(VLOOKUP("CTRL-"&N$3,'Release Controls'!$A$4:$I$10,9,FALSE),IFERROR(VLOOKUP("CTRL-"&N$3,'Runtime Controls'!$A$4:$I$9,9,FALSE),IFERROR(VLOOKUP("CTRL-"&N$3,'Lifecycle Controls'!$A$4:$I$6,9,FALSE),"—")))) -> Ineffective | O17: =IFERROR(VLOOKUP("CTRL-"&O$3,'Build Controls'!$A$4:$I$9,9,FALSE),IFERROR(VLOOKUP("CTRL-"&O$3,'Release Controls'!$A$4:$I$10,9,FALSE),IFERROR(VLOOKUP("CTRL-"&O$3,'Runtime Controls'!$A$4:$I$9,9,FALSE),IFERROR(VLOOKUP("CTRL-"&O$3,'Lifecycle Controls'!$A$4:$I$6,9,FALSE),"—")))) -> Ineffective | P17: =IFERROR(VLOOKUP("CTRL-"&P$3,'Build Controls'!$A$4:$I$9,9,FALSE),IFERROR(VLOOKUP("CTRL-"&P$3,'Release Controls'!$A$4:$I$10,9,FALSE),IFERROR(VLOOKUP("CTRL-"&P$3,'Runtime Controls'!$A$4:$I$9,9,FALSE),IFERROR(VLOOKUP("CTRL-"&P$3,'Lifecycle Controls'!$A$4:$I$6,9,FALSE),"—")))) -> Ineffective | Q17: =IFERROR(VLOOKUP("CTRL-"&Q$3,'Build Controls'!$A$4:$I$9,9,FALSE),IFERROR(VLOOKUP("CTRL-"&Q$3,'Release Controls'!$A$4:$I$10,9,FALSE),IFERROR(VLOOKUP("CTRL-"&Q$3,'Runtime Controls'!$A$4:$I$9,9,FALSE),IFERROR(VLOOKUP("CTRL-"&Q$3,'Lifecycle Controls'!$A$4:$I$6,9,FALSE),"—")))) -> Not Tested | R17: =IFERROR(VLOOKUP("CTRL-"&R$3,'Build Controls'!$A$4:$I$9,9,FALSE),IFERROR(VLOOKUP("CTRL-"&R$3,'Release Controls'!$A$4:$I$10,9,FALSE),IFERROR(VLOOKUP("CTRL-"&R$3,'Runtime Controls'!$A$4:$I$9,9,FALSE),IFERROR(VLOOKUP("CTRL-"&R$3,'Lifecycle Controls'!$A$4:$I$6,9,FALSE),"—")))) -> Not Tested | S17: =IFERROR(VLOOKUP("CTRL-"&S$3,'Build Controls'!$A$4:$I$9,9,FALSE),IFERROR(VLOOKUP("CTRL-"&S$3,'Release Controls'!$A$4:$I$11,9,FALSE),IFERROR(VLOOKUP("CTRL-"&S$3,'Runtime Controls'!$A$4:$I$9,9,FALSE),IFERROR(VLOOKUP("CTRL-"&S$3,'Lifecycle Controls'!$A$4:$I$6,9,FALSE),"—")))) -> Partially Effective | T17: =IFERROR(VLOOKUP("CTRL-"&T$3,'Build Controls'!$A$4:$I$9,9,FALSE),IFERROR(VLOOKUP("CTRL-"&T$3,'Release Controls'!$A$4:$I$10,9,FALSE),IFERROR(VLOOKUP("CTRL-"&T$3,'Runtime Controls'!$A$4:$I$9,9,FALSE),IFERROR(VLOOKUP("CTRL-"&T$3,'Lifecycle Controls'!$A$4:$I$6,9,FALSE),"—")))) -> Not Tested | U17: =IFERROR(VLOOKUP("CTRL-"&U$3,'Build Controls'!$A$4:$I$9,9,FALSE),IFERROR(VLOOKUP("CTRL-"&U$3,'Release Controls'!$A$4:$I$10,9,FALSE),IFERROR(VLOOKUP("CTRL-"&U$3,'Runtime Controls'!$A$4:$I$9,9,FALSE),IFERROR(VLOOKUP("CTRL-"&U$3,'Lifecycle Controls'!$A$4:$I$6,9,FALSE),"—")))) -> Ineffective | V17: =IFERROR(VLOOKUP("CTRL-"&V$3,'Build Controls'!$A$4:$I$9,9,FALSE),IFERROR(VLOOKUP("CTRL-"&V$3,'Release Controls'!$A$4:$I$10,9,FALSE),IFERROR(VLOOKUP("CTRL-"&V$3,'Runtime Controls'!$A$4:$I$9,9,FALSE),IFERROR(VLOOKUP("CTRL-"&V$3,'Lifecycle Controls'!$A$4:$I$6,9,FALSE),"—")))) -> Ineffective | W17: =IFERROR(VLOOKUP("CTRL-"&W$3,'Build Controls'!$A$4:$I$9,9,FALSE),IFERROR(VLOOKUP("CTRL-"&W$3,'Release Controls'!$A$4:$I$10,9,FALSE),IFERROR(VLOOKUP("CTRL-"&W$3,'Runtime Controls'!$A$4:$I$9,9,FALSE),IFERROR(VLOOKUP("CTRL-"&W$3,'Lifecycle Controls'!$A$4:$I$6,9,FALSE),"—")))) -> Ineffective | X17: =IFERROR(VLOOKUP("CTRL-"&X$3,'Build Controls'!$A$4:$I$9,9,FALSE),IFERROR(VLOOKUP("CTRL-"&X$3,'Release Controls'!$A$4:$I$10,9,FALSE),IFERROR(VLOOKUP("CTRL-"&X$3,'Runtime Controls'!$A$4:$I$9,9,FALSE),IFERROR(VLOOKUP("CTRL-"&X$3,'Lifecycle Controls'!$A$4:$I$6,9,FALSE),"—")))) -> Ineffective | Y17: =IFERROR(VLOOKUP("CTRL-"&Y$3,'Build Controls'!$A$4:$I$9,9,FALSE),IFERROR(VLOOKUP("CTRL-"&Y$3,'Release Controls'!$A$4:$I$10,9,FALSE),IFERROR(VLOOKUP("CTRL-"&Y$3,'Runtime Controls'!$A$4:$I$9,9,FALSE),IFERROR(VLOOKUP("CTRL-"&Y$3,'Lifecycle Controls'!$A$4:$I$6,9,FALSE),"—")))) -> Not Tested | Z17: =IFERROR(VLOOKUP("CTRL-"&Z$3,'Build Controls'!$A$4:$I$12,9,FALSE),IFERROR(VLOOKUP("CTRL-"&Z$3,'Release Controls'!$A$4:$I$10,9,FALSE),IFERROR(VLOOKUP("CTRL-"&Z$3,'Runtime Controls'!$A$4:$I$10,9,FALSE),IFERROR(VLOOKUP("CTRL-"&Z$3,'Lifecycle Controls'!$A$4:$I$6,9,FALSE),"—")))) -> Ineffective | AA17: =IFERROR(VLOOKUP("CTRL-"&AA$3,'Build Controls'!$A$4:$I$9,9,FALSE),IFERROR(VLOOKUP("CTRL-"&AA$3,'Release Controls'!$A$4:$I$10,9,FALSE),IFERROR(VLOOKUP("CTRL-"&AA$3,'Runtime Controls'!$A$4:$I$9,9,FALSE),IFERROR(VLOOKUP("CTRL-"&AA$3,'Lifecycle Controls'!$A$4:$I$6,9,FALSE),"—")))) -> Not Tested | AB17: =IFERROR(VLOOKUP("CTRL-"&AB$3,'Build Controls'!$A$4:$I$9,9,FALSE),IFERROR(VLOOKUP("CTRL-"&AB$3,'Release Controls'!$A$4:$I$10,9,FALSE),IFERROR(VLOOKUP("CTRL-"&AB$3,'Runtime Controls'!$A$4:$I$9,9,FALSE),IFERROR(VLOOKUP("CTRL-"&AB$3,'Lifecycle Controls'!$A$4:$I$6,9,FALSE),"—")))) -> Effective | AC17: =IFERROR(VLOOKUP("CTRL-"&AC$3,'Build Controls'!$A$4:$I$9,9,FALSE),IFERROR(VLOOKUP("CTRL-"&AC$3,'Release Controls'!$A$4:$I$10,9,FALSE),IFERROR(VLOOKUP("CTRL-"&AC$3,'Runtime Controls'!$A$4:$I$9,9,FALSE),IFERROR(VLOOKUP("CTRL-"&AC$3,'Lifecycle Controls'!$A$4:$I$6,9,FALSE),"—")))) -> Not Tested | AD17: =IFERROR(VLOOKUP("CTRL-"&AD$3,'Build Controls'!$A$4:$I$12,9,FALSE),IFERROR(VLOOKUP("CTRL-"&AD$3,'Release Controls'!$A$4:$I$10,9,FALSE),IFERROR(VLOOKUP("CTRL-"&AD$3,'Runtime Controls'!$A$4:$I$10,9,FALSE),IFERROR(VLOOKUP("CTRL-"&AD$3,'Lifecycle Controls'!$A$4:$I$8,9,FALSE),"—")))) -> Effective | AE17: =IFERROR(VLOOKUP("CTRL-"&AE$3,'Build Controls'!$A$4:$I$12,9,FALSE),IFERROR(VLOOKUP("CTRL-"&AE$3,'Release Controls'!$A$4:$I$10,9,FALSE),IFERROR(VLOOKUP("CTRL-"&AE$3,'Runtime Controls'!$A$4:$I$10,9,FALSE),IFERROR(VLOOKUP("CTRL-"&AE$3,'Lifecycle Controls'!$A$4:$I$8,9,FALSE),"—")))) -> Partially Effective
B18: Effectiveness weight | C18: =IFERROR(VLOOKUP(C17,'Scoring Legend'!$B$29:$C$32,2,FALSE),0) -> 0 | D18: =IFERROR(VLOOKUP(D17,'Scoring Legend'!$B$29:$C$32,2,FALSE),0) -> 0 | E18: =IFERROR(VLOOKUP(E17,'Scoring Legend'!$B$29:$C$32,2,FALSE),0) -> 0 | F18: =IFERROR(VLOOKUP(F17,'Scoring Legend'!$B$29:$C$32,2,FALSE),0) -> 0 | G18: =IFERROR(VLOOKUP(G17,'Scoring Legend'!$B$29:$C$32,2,FALSE),0) -> 0 | H18: =IFERROR(VLOOKUP(H17,'Scoring Legend'!$B$29:$C$32,2,FALSE),0) -> 0 | I18: =IFERROR(VLOOKUP(I17,'Scoring Legend'!$B$29:$C$32,2,FALSE),0) -> 0 | J18: =IFERROR(VLOOKUP(J17,'Scoring Legend'!$B$29:$C$32,2,FALSE),0) -> 0 | ... AE18: =IFERROR(VLOOKUP(AE17,'Scoring Legend'!$B$29:$C$32,2,FALSE),0) -> 0.5
A19: X = control mitigates the risk. Control IDs are CTRL-00xx; see the control tabs for names. Row total = controls mitigating each risk; bottom row = risks each control addresses.

Sheet Build Controls
A1: Build Controls — SDLC Controls
A2: CONTROL | F2: RISK COVERAGE | H2: ASSESSMENT | J2: OWNER & ACTION
A3: Control ID | B3: Control | C3: Objective / Description | D3: Control Type | E3: Control Nature | F3: Risks Mitigated | G3: # Risks | H3: Implementation Status | I3: Control Effectiveness | J3: Control Owner | K3: Evidence / Reference | L3: Action Plan / Notes | M3: Target Date | N3: Status
A4: CTRL-0001 | B4: Version Control | C4: All source code and configuration is managed in version control with full, traceable history. | D4: Preventive | E4: Manual | F4: =IF(COUNTIF('Risk-Control Matrix'!C4:C12,"X")=0,"—",_xlfn.TEXTJOIN(", ",TRUE(),IF('Risk-Control Matrix'!C4="X",RIGHT('Risk-Control Matrix'!$A$4,4),""),IF('Risk-Control Matrix'!C5="X",RIGHT('Risk-Control Matrix'!$A$5,4),""),IF('Risk-Control Matrix'!C6="X",RIGHT('Risk-Control Matrix'!$A$6,4),""),IF('Risk-Control Matrix'!C7="X",RIGHT('Risk-Control Matrix'!$A$7,4),""),IF('Risk-Control Matrix'!C8="X",RIGHT('Risk-Control Matrix'!$A$8,4),""),IF('Risk-Control Matrix'!C9="X",RIGHT('Risk-Control Matrix'!$A$9,4),""),IF('Risk-Control Matrix'!C10="X",RIGHT('Risk-Control Matrix'!$A$10,4),""),IF('Risk-Control Matrix'!C11="X",RIGHT('Risk-Control Matrix'!$A$11,4),""),IF('Risk-Control Matrix'!C12="X",RIGHT('Risk-Control Matrix'!$A$12,4),""))) -> 0002, 0004, 0008 | G4: =COUNTIF('Risk-Control Matrix'!C4:C12,"X") -> 3 | H4: Implemented | I4: Ineffective | N4: To Do
A5: CTRL-0002 | B5: Artifact Binary Provenance | C5: Build artifacts are traceable to their source commit and build; provenance is attested and verifiable. | D5: Detective | E5: Automated | F5: =IF(COUNTIF('Risk-Control Matrix'!D4:D12,"X")=0,"—",_xlfn.TEXTJOIN(", ",TRUE(),IF('Risk-Control Matrix'!D4="X",RIGHT('Risk-Control Matrix'!$A$4,4),""),IF('Risk-Control Matrix'!D5="X",RIGHT('Risk-Control Matrix'!$A$5,4),""),IF('Risk-Control Matrix'!D6="X",RIGHT('Risk-Control Matrix'!$A$6,4),""),IF('Risk-Control Matrix'!D7="X",RIGHT('Risk-Control Matrix'!$A$7,4),""),IF('Risk-Control Matrix'!D8="X",RIGHT('Risk-Control Matrix'!$A$8,4),""),IF('Risk-Control Matrix'!D9="X",RIGHT('Risk-Control Matrix'!$A$9,4),""),IF('Risk-Control Matrix'!D10="X",RIGHT('Risk-Control Matrix'!$A$10,4),""),IF('Risk-Control Matrix'!D11="X",RIGHT('Risk-Control Matrix'!$A$11,4),""),IF('Risk-Control Matrix'!D12="X",RIGHT('Risk-Control Matrix'!$A$12,4),""))) -> 0001, 0003, 0006 | G5: =COUNTIF('Risk-Control Matrix'!D4:D12,"X") -> 3 | H5: Partially Implemented | I5: Ineffective | N5: In Progress
A6: CTRL-0003 | B6: Controlled Build Environment | C6: Builds run in a controlled, reproducible environment using approved, hardened toolchains. | D6: Corrective | E6: Hybrid | F6: =IF(COUNTIF('Risk-Control Matrix'!E4:E12,"X")=0,"—",_xlfn.TEXTJOIN(", ",TRUE(),IF('Risk-Control Matrix'!E4="X",RIGHT('Risk-Control Matrix'!$A$4,4),""),IF('Risk-Control Matrix'!E5="X",RIGHT('Risk-Control Matrix'!$A$5,4),""),IF('Risk-Control Matrix'!E6="X",RIGHT('Risk-Control Matrix'!$A$6,4),""),IF('Risk-Control Matrix'!E7="X",RIGHT('Risk-Control Matrix'!$A$7,4),""),IF('Risk-Control Matrix'!E8="X",RIGHT('Risk-Control Matrix'!$A$8,4),""),IF('Risk-Control Matrix'!E9="X",RIGHT('Risk-Control Matrix'!$A$9,4),""),IF('Risk-Control Matrix'!E10="X",RIGHT('Risk-Control Matrix'!$A$10,4),""),IF('Risk-Control Matrix'!E11="X",RIGHT('Risk-Control Matrix'!$A$11,4),""),IF('Risk-Control Matrix'!E12="X",RIGHT('Risk-Control Matrix'!$A$12,4),""))) -> 0001 | G6: =COUNTIF('Risk-Control Matrix'!E4:E12,"X") -> 1 | H6: Planned | I6: Ineffective | N6: Implemented
A7: CTRL-0004 | B7: Dependency Management | C7: Third-party and open-source dependencies are inventoried, approved and kept current; SBOM maintained. | D7: Preventive & Detective | E7: Automated | F7: =IF(COUNTIF('Risk-Control Matrix'!F4:F12,"X")=0,"—",_xlfn.TEXTJOIN(", ",TRUE(),IF('Risk-Control Matrix'!F4="X",RIGHT('Risk-Control Matrix'!$A$4,4),""),IF('Risk-Control Matrix'!F5="X",RIGHT('Risk-Control Matrix'!$A$5,4),""),IF('Risk-Control Matrix'!F6="X",RIGHT('Risk-Control Matrix'!$A$6,4),""),IF('Risk-Control Matrix'!F7="X",RIGHT('Risk-Control Matrix'!$A$7,4),""),IF('Risk-Control Matrix'!F8="X",RIGHT('Risk-Control Matrix'!$A$8,4),""),IF('Risk-Control Matrix'!F9="X",RIGHT('Risk-Control Matrix'!$A$9,4),""),IF('Risk-Control Matrix'!F10="X",RIGHT('Risk-Control Matrix'!$A$10,4),""),IF('Risk-Control Matrix'!F11="X",RIGHT('Risk-Control Matrix'!$A$11,4),""),IF('Risk-Control Matrix'!F12="X",RIGHT('Risk-Control Matrix'!$A$12,4),""))) -> 0001, 0005 | G7: =COUNTIF('Risk-Control Matrix'!F4:F12,"X") -> 2 | H7: Not Implemented | I7: Ineffective | N7: Accepted
A8: CTRL-0005 | B8: Infrastructure and Configuration as Code | C8: Infrastructure and configuration are defined as code, version-controlled and peer-reviewed. | D8: Detective & Corrective | E8: Automated | F8: =IF(COUNTIF('Risk-Control Matrix'!G4:G12,"X")=0,"—",_xlfn.TEXTJOIN(", ",TRUE(),IF('Risk-Control Matrix'!G4="X",RIGHT('Risk-Control Matrix'!$A$4,4),""),IF('Risk-Control Matrix'!G5="X",RIGHT('Risk-Control Matrix'!$A$5,4),""),IF('Risk-Control Matrix'!G6="X",RIGHT('Risk-Control Matrix'!$A$6,4),""),IF('Risk-Control Matrix'!G7="X",RIGHT('Risk-Control Matrix'!$A$7,4),""),IF('Risk-Control Matrix'!G8="X",RIGHT('Risk-Control Matrix'!$A$8,4),""),IF('Risk-Control Matrix'!G9="X",RIGHT('Risk-Control Matrix'!$A$9,4),""),IF('Risk-Control Matrix'!G10="X",RIGHT('Risk-Control Matrix'!$A$10,4),""),IF('Risk-Control Matrix'!G11="X",RIGHT('Risk-Control Matrix'!$A$11,4),""),IF('Risk-Control Matrix'!G12="X",RIGHT('Risk-Control Matrix'!$A$12,4),""))) -> 0008 | G8: =COUNTIF('Risk-Control Matrix'!G4:G12,"X") -> 1 | H8: Not Implemented | I8: Not Tested | N8: Closed
A9: CTRL-0006 | B9: Secrets Scanning | C9: Code and artifacts are scanned to detect secrets/credentials before reaching shared repositories. | D9: Preventive & Corrective | E9: Automated | F9: =IF(COUNTIF('Risk-Control Matrix'!H4:H12,"X")=0,"—",_xlfn.TEXTJOIN(", ",TRUE(),IF('Risk-Control Matrix'!H4="X",RIGHT('Risk-Control Matrix'!$A$4,4),""),IF('Risk-Control Matrix'!H5="X",RIGHT('Risk-Control Matrix'!$A$5,4),""),IF('Risk-Control Matrix'!H6="X",RIGHT('Risk-Control Matrix'!$A$6,4),""),IF('Risk-Control Matrix'!H7="X",RIGHT('Risk-Control Matrix'!$A$7,4),""),IF('Risk-Control Matrix'!H8="X",RIGHT('Risk-Control Matrix'!$A$8,4),""),IF('Risk-Control Matrix'!H9="X",RIGHT('Risk-Control Matrix'!$A$9,4),""),IF('Risk-Control Matrix'!H10="X",RIGHT('Risk-Control Matrix'!$A$10,4),""),IF('Risk-Control Matrix'!H11="X",RIGHT('Risk-Control Matrix'!$A$11,4),""),IF('Risk-Control Matrix'!H12="X",RIGHT('Risk-Control Matrix'!$A$12,4),""))) -> 0004 | G9: =COUNTIF('Risk-Control Matrix'!H4:H12,"X") -> 1 | H9: Not Implemented | I9: Ineffective | N9: Closed
A10: CTRL-0024 | B10: Software Bill of Materials (SBOM) Generation & Attestation | C10: Enforce that every build automatically generates a standard SBOM (e.g., CycloneDX or SPDX format) and cryptographically signs it to prevent tampering. | D10: Preventive & Detective | E10: Automated | F10: 1 | G10: 1 | H10: Not Implemented | I10: Ineffective | N10: To Do
A11: CTRL-0025 | B11: Dependency Firewall & Vetted Registries | C11: Restrict CI/CD runners from pulling packages directly from public registries without routing through a proxy that blocks malicious or unvetted packages. | D11: Preventive | E11: Automated | F11: 1 | G11: 1 | H11: Not Implemented | I11: Ineffective | N11: To Do
A12: CTRL-0026 | B12: Infrastructure as Code (IaC) Static Analysis | C12: Automated pre-deployment security scanning of cloud configuration files (Terraform templates, Helm charts, Kubernetes manifests) to catch misconfigurations before deployment. | D12: Preventive | E12: Automated | F12: 5 | G12: 1 | H12: Not Implemented | I12: Ineffective | N12: To Do

Sheet Release Controls
A1: Release Controls — SDLC Controls
A2: CONTROL | F2: RISK COVERAGE | H2: ASSESSMENT | J2: OWNER & ACTION
A3: Control ID | B3: Control | C3: Objective / Description | D3: Control Type | E3: Control Nature | F3: Risks Mitigated | G3: # Risks | H3: Implementation Status | I3: Control Effectiveness | J3: Control Owner | K3: Evidence / Reference | L3: Action Plan / Notes | M3: Target Date | N3: Status
A4: CTRL-0007 | B4: Code Review | C4: Changes are peer-reviewed and approved before being merged or released. | D4: Preventive | E4: Hybrid | F4: =IF(COUNTIF('Risk-Control Matrix'!L4:L15,"X")=0,"—",_xlfn.TEXTJOIN(", ",TRUE(),IF('Risk-Control Matrix'!L4="X",RIGHT('Risk-Control Matrix'!$A$4,4),""),IF('Risk-Control Matrix'!L5="X",RIGHT('Risk-Control Matrix'!$A$5,4),""),IF('Risk-Control Matrix'!L6="X",RIGHT('Risk-Control Matrix'!$A$6,4),""),IF('Risk-Control Matrix'!L7="X",RIGHT('Risk-Control Matrix'!$A$7,4),""),IF('Risk-Control Matrix'!L8="X",RIGHT('Risk-Control Matrix'!$A$8,4),""),IF('Risk-Control Matrix'!L9="X",RIGHT('Risk-Control Matrix'!$A$9,4),""),IF('Risk-Control Matrix'!L10="X",RIGHT('Risk-Control Matrix'!$A$10,4),""),IF('Risk-Control Matrix'!L11="X",RIGHT('Risk-Control Matrix'!$A$11,4),""),IF('Risk-Control Matrix'!L12="X",RIGHT('Risk-Control Matrix'!$A$12,4),""),IF('Risk-Control Matrix'!L13="X",RIGHT('Risk-Control Matrix'!$A$13,4),""),IF('Risk-Control Matrix'!L14="X",RIGHT('Risk-Control Matrix'!$A$14,4),""),IF('Risk-Control Matrix'!L15="X",RIGHT('Risk-Control Matrix'!$A$15,4),""))) -> 0002, 0006, 0010 | G4: =COUNTIF('Risk-Control Matrix'!L4:L15,"X") -> 3 | H4: Implemented | I4: Effective | N4: Implemented
A5: CTRL-0008 | B5: Quality Assurance | C5: Automated and manual testing validates functionality and quality before release. | D5: Detective | E5: Hybrid | F5: =IF(COUNTIF('Risk-Control Matrix'!M4:M15,"X")=0,"—",_xlfn.TEXTJOIN(", ",TRUE(),IF('Risk-Control Matrix'!M4="X",RIGHT('Risk-Control Matrix'!$A$4,4),""),IF('Risk-Control Matrix'!M5="X",RIGHT('Risk-Control Matrix'!$A$5,4),""),IF('Risk-Control Matrix'!M6="X",RIGHT('Risk-Control Matrix'!$A$6,4),""),IF('Risk-Control Matrix'!M7="X",RIGHT('Risk-Control Matrix'!$A$7,4),""),IF('Risk-Control Matrix'!M8="X",RIGHT('Risk-Control Matrix'!$A$8,4),""),IF('Risk-Control Matrix'!M9="X",RIGHT('Risk-Control Matrix'!$A$9,4),""),IF('Risk-Control Matrix'!M10="X",RIGHT('Risk-Control Matrix'!$A$10,4),""),IF('Risk-Control Matrix'!M11="X",RIGHT('Risk-Control Matrix'!$A$11,4),""),IF('Risk-Control Matrix'!M12="X",RIGHT('Risk-Control Matrix'!$A$12,4),""),IF('Risk-Control Matrix'!M13="X",RIGHT('Risk-Control Matrix'!$A$13,4),""),IF('Risk-Control Matrix'!M14="X",RIGHT('Risk-Control Matrix'!$A$14,4),""),IF('Risk-Control Matrix'!M15="X",RIGHT('Risk-Control Matrix'!$A$15,4),""))) -> 0005 | G5: =COUNTIF('Risk-Control Matrix'!M4:M15,"X") -> 1 | H5: Not Implemented | I5: Not Tested | N5: To Do
A6: CTRL-0020 | B6: Vulnerability Scanning — SAST | C6: Static application security testing detects code-level vulnerabilities before release. | D6: Detective | E6: Automated | F6: =IF(COUNTIF('Risk-Control Matrix'!N4:N15,"X")=0,"—",_xlfn.TEXTJOIN(", ",TRUE(),IF('Risk-Control Matrix'!N4="X",RIGHT('Risk-Control Matrix'!$A$4,4),""),IF('Risk-Control Matrix'!N5="X",RIGHT('Risk-Control Matrix'!$A$5,4),""),IF('Risk-Control Matrix'!N6="X",RIGHT('Risk-Control Matrix'!$A$6,4),""),IF('Risk-Control Matrix'!N7="X",RIGHT('Risk-Control Matrix'!$A$7,4),""),IF('Risk-Control Matrix'!N8="X",RIGHT('Risk-Control Matrix'!$A$8,4),""),IF('Risk-Control Matrix'!N9="X",RIGHT('Risk-Control Matrix'!$A$9,4),""),IF('Risk-Control Matrix'!N10="X",RIGHT('Risk-Control Matrix'!$A$10,4),""),IF('Risk-Control Matrix'!N11="X",RIGHT('Risk-Control Matrix'!$A$11,4),""),IF('Risk-Control Matrix'!N12="X",RIGHT('Risk-Control Matrix'!$A$12,4),""),IF('Risk-Control Matrix'!N13="X",RIGHT('Risk-Control Matrix'!$A$13,4),""),IF('Risk-Control Matrix'!N14="X",RIGHT('Risk-Control Matrix'!$A$14,4),""),IF('Risk-Control Matrix'!N15="X",RIGHT('Risk-Control Matrix'!$A$15,4),""))) -> 0001, 0005 | G6: =COUNTIF('Risk-Control Matrix'!N4:N15,"X") -> 2 | H6: Implemented | I6: Ineffective | N6: Implemented
A7: CTRL-0021 | B7: Vulnerability Scanning — SCA | C7: Software composition analysis detects vulnerable dependencies before release. | D7: Detective | E7: Automated | F7: =IF(COUNTIF('Risk-Control Matrix'!O4:O15,"X")=0,"—",_xlfn.TEXTJOIN(", ",TRUE(),IF('Risk-Control Matrix'!O4="X",RIGHT('Risk-Control Matrix'!$A$4,4),""),IF('Risk-Control Matrix'!O5="X",RIGHT('Risk-Control Matrix'!$A$5,4),""),IF('Risk-Control Matrix'!O6="X",RIGHT('Risk-Control Matrix'!$A$6,4),""),IF('Risk-Control Matrix'!O7="X",RIGHT('Risk-Control Matrix'!$A$7,4),""),IF('Risk-Control Matrix'!O8="X",RIGHT('Risk-Control Matrix'!$A$8,4),""),IF('Risk-Control Matrix'!O9="X",RIGHT('Risk-Control Matrix'!$A$9,4),""),IF('Risk-Control Matrix'!O10="X",RIGHT('Risk-Control Matrix'!$A$10,4),""),IF('Risk-Control Matrix'!O11="X",RIGHT('Risk-Control Matrix'!$A$11,4),""),IF('Risk-Control Matrix'!O12="X",RIGHT('Risk-Control Matrix'!$A$12,4),""),IF('Risk-Control Matrix'!O13="X",RIGHT('Risk-Control Matrix'!$A$13,4),""),IF('Risk-Control Matrix'!O14="X",RIGHT('Risk-Control Matrix'!$A$14,4),""),IF('Risk-Control Matrix'!O15="X",RIGHT('Risk-Control Matrix'!$A$15,4),""))) -> 0001, 0005 | G7: =COUNTIF('Risk-Control Matrix'!O4:O15,"X") -> 2 | H7: Implemented | I7: Ineffective | N7: Implemented
A8: CTRL-0022 | B8: Vulnerability Scanning — Containers | C8: Container images are scanned for vulnerabilities before release. | D8: Detective | E8: Automated | F8: =IF(COUNTIF('Risk-Control Matrix'!P4:P15,"X")=0,"—",_xlfn.TEXTJOIN(", ",TRUE(),IF('Risk-Control Matrix'!P4="X",RIGHT('Risk-Control Matrix'!$A$4,4),""),IF('Risk-Control Matrix'!P5="X",RIGHT('Risk-Control Matrix'!$A$5,4),""),IF('Risk-Control Matrix'!P6="X",RIGHT('Risk-Control Matrix'!$A$6,4),""),IF('Risk-Control Matrix'!P7="X",RIGHT('Risk-Control Matrix'!$A$7,4),""),IF('Risk-Control Matrix'!P8="X",RIGHT('Risk-Control Matrix'!$A$8,4),""),IF('Risk-Control Matrix'!P9="X",RIGHT('Risk-Control Matrix'!$A$9,4),""),IF('Risk-Control Matrix'!P10="X",RIGHT('Risk-Control Matrix'!$A$10,4),""),IF('Risk-Control Matrix'!P11="X",RIGHT('Risk-Control Matrix'!$A$11,4),""),IF('Risk-Control Matrix'!P12="X",RIGHT('Risk-Control Matrix'!$A$12,4),""),IF('Risk-Control Matrix'!P13="X",RIGHT('Risk-Control Matrix'!$A$13,4),""),IF('Risk-Control Matrix'!P14="X",RIGHT('Risk-Control Matrix'!$A$14,4),""),IF('Risk-Control Matrix'!P15="X",RIGHT('Risk-Control Matrix'!$A$15,4),""))) -> 0001, 0005 | G8: =COUNTIF('Risk-Control Matrix'!P4:P15,"X") -> 2 | H8: Implemented | I8: Ineffective | N8: Implemented
A9: CTRL-0010 | B9: Deployment Approvals | C9: Production deployments require defined approvals and must pass required gates. | D9: Preventive | E9: Hybrid | F9: =IF(COUNTIF('Risk-Control Matrix'!Q4:Q15,"X")=0,"—",_xlfn.TEXTJOIN(", ",TRUE(),IF('Risk-Control Matrix'!Q4="X",RIGHT('Risk-Control Matrix'!$A$4,4),""),IF('Risk-Control Matrix'!Q5="X",RIGHT('Risk-Control Matrix'!$A$5,4),""),IF('Risk-Control Matrix'!Q6="X",RIGHT('Risk-Control Matrix'!$A$6,4),""),IF('Risk-Control Matrix'!Q7="X",RIGHT('Risk-Control Matrix'!$A$7,4),""),IF('Risk-Control Matrix'!Q8="X",RIGHT('Risk-Control Matrix'!$A$8,4),""),IF('Risk-Control Matrix'!Q9="X",RIGHT('Risk-Control Matrix'!$A$9,4),""),IF('Risk-Control Matrix'!Q10="X",RIGHT('Risk-Control Matrix'!$A$10,4),""),IF('Risk-Control Matrix'!Q11="X",RIGHT('Risk-Control Matrix'!$A$11,4),""),IF('Risk-Control Matrix'!Q12="X",RIGHT('Risk-Control Matrix'!$A$12,4),""),IF('Risk-Control Matrix'!Q13="X",RIGHT('Risk-Control Matrix'!$A$13,4),""),IF('Risk-Control Matrix'!Q14="X",RIGHT('Risk-Control Matrix'!$A$14,4),""),IF('Risk-Control Matrix'!Q15="X",RIGHT('Risk-Control Matrix'!$A$15,4),""))) -> 0002, 0003, 0006 | G9: =COUNTIF('Risk-Control Matrix'!Q4:Q15,"X") -> 3 | H9: Implemented | I9: Not Tested | N9: Implemented
A10: CTRL-0023 | B10: Feature Flags | C10: Functionality is controlled via feature flags to enable safe, reversible release. | D10: Corrective | E10: Automated | F10: =IF(COUNTIF('Risk-Control Matrix'!R4:R15,"X")=0,"—",_xlfn.TEXTJOIN(", ",TRUE(),IF('Risk-Control Matrix'!R4="X",RIGHT('Risk-Control Matrix'!$A$4,4),""),IF('Risk-Control Matrix'!R5="X",RIGHT('Risk-Control Matrix'!$A$5,4),""),IF('Risk-Control Matrix'!R6="X",RIGHT('Risk-Control Matrix'!$A$6,4),""),IF('Risk-Control Matrix'!R7="X",RIGHT('Risk-Control Matrix'!$A$7,4),""),IF('Risk-Control Matrix'!R8="X",RIGHT('Risk-Control Matrix'!$A$8,4),""),IF('Risk-Control Matrix'!R9="X",RIGHT('Risk-Control Matrix'!$A$9,4),""),IF('Risk-Control Matrix'!R10="X",RIGHT('Risk-Control Matrix'!$A$10,4),""),IF('Risk-Control Matrix'!R11="X",RIGHT('Risk-Control Matrix'!$A$11,4),""),IF('Risk-Control Matrix'!R12="X",RIGHT('Risk-Control Matrix'!$A$12,4),""),IF('Risk-Control Matrix'!R13="X",RIGHT('Risk-Control Matrix'!$A$13,4),""),IF('Risk-Control Matrix'!R14="X",RIGHT('Risk-Control Matrix'!$A$14,4),""),IF('Risk-Control Matrix'!R15="X",RIGHT('Risk-Control Matrix'!$A$15,4),""))) -> — | G10: =COUNTIF('Risk-Control Matrix'!R4:R15,"X") -> 0 | H10: Not Implemented | I10: Not Tested | N10: To Do
A11: CTRL-0030 | B11: Automated API Schema & Contract Verification | C11: Validate live staging application network interfaces against strict OpenAPI schemas and execute automated behavioral fuzz tests to discover object-level authorization vulnerabilities. | D11: Corrective | E11: Automated | F11: =IF(COUNTIF('Risk-Control Matrix'!S4:S15,"X")=0,"—",_xlfn.TEXTJOIN(", ",TRUE(),IF('Risk-Control Matrix'!S4="X",RIGHT('Risk-Control Matrix'!$A$4,4),""),IF('Risk-Control Matrix'!S5="X",RIGHT('Risk-Control Matrix'!$A$5,4),""),IF('Risk-Control Matrix'!S6="X",RIGHT('Risk-Control Matrix'!$A$6,4),""),IF('Risk-Control Matrix'!S7="X",RIGHT('Risk-Control Matrix'!$A$7,4),""),IF('Risk-Control Matrix'!S8="X",RIGHT('Risk-Control Matrix'!$A$8,4),""),IF('Risk-Control Matrix'!S9="X",RIGHT('Risk-Control Matrix'!$A$9,4),""),IF('Risk-Control Matrix'!S10="X",RIGHT('Risk-Control Matrix'!$A$10,4),""),IF('Risk-Control Matrix'!S11="X",RIGHT('Risk-Control Matrix'!$A$11,4),""),IF('Risk-Control Matrix'!S12="X",RIGHT('Risk-Control Matrix'!$A$12,4),""),IF('Risk-Control Matrix'!S13="X",RIGHT('Risk-Control Matrix'!$A$13,4),""),IF('Risk-Control Matrix'!S14="X",RIGHT('Risk-Control Matrix'!$A$14,4),""),IF('Risk-Control Matrix'!S15="X",RIGHT('Risk-Control Matrix'!$A$15,4),""))) -> 0012 | G11: =COUNTIF('Risk-Control Matrix'!S4:S15,"X") -> 1 | H11: Not Implemented | I11: Partially Effective | N11: To Do

Sheet Runtime Controls
A1: Runtime Controls — SDLC Controls
A2: CONTROL | F2: RISK COVERAGE | H2: ASSESSMENT | J2: OWNER & ACTION
A3: Control ID | B3: Control | C3: Objective / Description | D3: Control Type | E3: Control Nature | F3: Risks Mitigated | G3: # Risks | H3: Implementation Status | I3: Control Effectiveness | J3: Control Owner | K3: Evidence / Reference | L3: Action Plan / Notes | M3: Target Date | N3: Status
A4: CTRL-0012 | B4: Change Records | C4: Every production change is captured in a traceable, auditable change record. | D4: Detective | E4: Automated | F4: =IF(COUNTIF('Risk-Control Matrix'!T4:T12,"X")=0,"—",_xlfn.TEXTJOIN(", ",TRUE(),IF('Risk-Control Matrix'!T4="X",RIGHT('Risk-Control Matrix'!$A$4,4),""),IF('Risk-Control Matrix'!T5="X",RIGHT('Risk-Control Matrix'!$A$5,4),""),IF('Risk-Control Matrix'!T6="X",RIGHT('Risk-Control Matrix'!$A$6,4),""),IF('Risk-Control Matrix'!T7="X",RIGHT('Risk-Control Matrix'!$A$7,4),""),IF('Risk-Control Matrix'!T8="X",RIGHT('Risk-Control Matrix'!$A$8,4),""),IF('Risk-Control Matrix'!T9="X",RIGHT('Risk-Control Matrix'!$A$9,4),""),IF('Risk-Control Matrix'!T10="X",RIGHT('Risk-Control Matrix'!$A$10,4),""),IF('Risk-Control Matrix'!T11="X",RIGHT('Risk-Control Matrix'!$A$11,4),""),IF('Risk-Control Matrix'!T12="X",RIGHT('Risk-Control Matrix'!$A$12,4),""))) -> 0002, 0006, 0008 | G4: =COUNTIF('Risk-Control Matrix'!T4:T12,"X") -> 3 | H4: Not Implemented | I4: Not Tested | N4: To Do
A5: CTRL-0013 | B5: Deployment Controls | C5: Only verified, approved artifacts can be deployed; deployment mechanisms are controlled. | D5: Preventive | E5: Automated | F5: =IF(COUNTIF('Risk-Control Matrix'!U4:U12,"X")=0,"—",_xlfn.TEXTJOIN(", ",TRUE(),IF('Risk-Control Matrix'!U4="X",RIGHT('Risk-Control Matrix'!$A$4,4),""),IF('Risk-Control Matrix'!U5="X",RIGHT('Risk-Control Matrix'!$A$5,4),""),IF('Risk-Control Matrix'!U6="X",RIGHT('Risk-Control Matrix'!$A$6,4),""),IF('Risk-Control Matrix'!U7="X",RIGHT('Risk-Control Matrix'!$A$7,4),""),IF('Risk-Control Matrix'!U8="X",RIGHT('Risk-Control Matrix'!$A$8,4),""),IF('Risk-Control Matrix'!U9="X",RIGHT('Risk-Control Matrix'!$A$9,4),""),IF('Risk-Control Matrix'!U10="X",RIGHT('Risk-Control Matrix'!$A$10,4),""),IF('Risk-Control Matrix'!U11="X",RIGHT('Risk-Control Matrix'!$A$11,4),""),IF('Risk-Control Matrix'!U12="X",RIGHT('Risk-Control Matrix'!$A$12,4),""))) -> 0001, 0002, 0003, 0008 | G5: =COUNTIF('Risk-Control Matrix'!U4:U12,"X") -> 4 | H5: Not Implemented | I5: Ineffective | N5: Implemented
A6: CTRL-0014 | B6: Secrets Management | C6: Runtime secrets are stored, rotated and accessed through a managed secrets solution. | D6: Preventive | E6: Automated | F6: =IF(COUNTIF('Risk-Control Matrix'!V4:V12,"X")=0,"—",_xlfn.TEXTJOIN(", ",TRUE(),IF('Risk-Control Matrix'!V4="X",RIGHT('Risk-Control Matrix'!$A$4,4),""),IF('Risk-Control Matrix'!V5="X",RIGHT('Risk-Control Matrix'!$A$5,4),""),IF('Risk-Control Matrix'!V6="X",RIGHT('Risk-Control Matrix'!$A$6,4),""),IF('Risk-Control Matrix'!V7="X",RIGHT('Risk-Control Matrix'!$A$7,4),""),IF('Risk-Control Matrix'!V8="X",RIGHT('Risk-Control Matrix'!$A$8,4),""),IF('Risk-Control Matrix'!V9="X",RIGHT('Risk-Control Matrix'!$A$9,4),""),IF('Risk-Control Matrix'!V10="X",RIGHT('Risk-Control Matrix'!$A$10,4),""),IF('Risk-Control Matrix'!V11="X",RIGHT('Risk-Control Matrix'!$A$11,4),""),IF('Risk-Control Matrix'!V12="X",RIGHT('Risk-Control Matrix'!$A$12,4),""))) -> 0002, 0004, 0007 | G6: =COUNTIF('Risk-Control Matrix'!V4:V12,"X") -> 3 | H6: Not Implemented | I6: Ineffective | N6: To Do
A7: CTRL-0015 | B7: System Access Controls | C7: Production access is least-privilege, authenticated, time-bound and logged. | D7: Preventive | E7: Hybrid | F7: =IF(COUNTIF('Risk-Control Matrix'!W4:W12,"X")=0,"—",_xlfn.TEXTJOIN(", ",TRUE(),IF('Risk-Control Matrix'!W4="X",RIGHT('Risk-Control Matrix'!$A$4,4),""),IF('Risk-Control Matrix'!W5="X",RIGHT('Risk-Control Matrix'!$A$5,4),""),IF('Risk-Control Matrix'!W6="X",RIGHT('Risk-Control Matrix'!$A$6,4),""),IF('Risk-Control Matrix'!W7="X",RIGHT('Risk-Control Matrix'!$A$7,4),""),IF('Risk-Control Matrix'!W8="X",RIGHT('Risk-Control Matrix'!$A$8,4),""),IF('Risk-Control Matrix'!W9="X",RIGHT('Risk-Control Matrix'!$A$9,4),""),IF('Risk-Control Matrix'!W10="X",RIGHT('Risk-Control Matrix'!$A$10,4),""),IF('Risk-Control Matrix'!W11="X",RIGHT('Risk-Control Matrix'!$A$11,4),""),IF('Risk-Control Matrix'!W12="X",RIGHT('Risk-Control Matrix'!$A$12,4),""))) -> 0002, 0004, 0006, 0007, 0009 | G7: =COUNTIF('Risk-Control Matrix'!W4:W12,"X") -> 5 | H7: Not Implemented | I7: Ineffective | N7: To Do
A8: CTRL-0016 | B8: Runtime Workload Monitoring | C8: Running workloads are monitored to detect anomalous or unauthorised activity. | D8: Detective | E8: Automated | F8: =IF(COUNTIF('Risk-Control Matrix'!X4:X12,"X")=0,"—",_xlfn.TEXTJOIN(", ",TRUE(),IF('Risk-Control Matrix'!X4="X",RIGHT('Risk-Control Matrix'!$A$4,4),""),IF('Risk-Control Matrix'!X5="X",RIGHT('Risk-Control Matrix'!$A$5,4),""),IF('Risk-Control Matrix'!X6="X",RIGHT('Risk-Control Matrix'!$A$6,4),""),IF('Risk-Control Matrix'!X7="X",RIGHT('Risk-Control Matrix'!$A$7,4),""),IF('Risk-Control Matrix'!X8="X",RIGHT('Risk-Control Matrix'!$A$8,4),""),IF('Risk-Control Matrix'!X9="X",RIGHT('Risk-Control Matrix'!$A$9,4),""),IF('Risk-Control Matrix'!X10="X",RIGHT('Risk-Control Matrix'!$A$10,4),""),IF('Risk-Control Matrix'!X11="X",RIGHT('Risk-Control Matrix'!$A$11,4),""),IF('Risk-Control Matrix'!X12="X",RIGHT('Risk-Control Matrix'!$A$12,4),""))) -> 0001, 0002, 0003, 0005, 0006, 0009 | G8: =COUNTIF('Risk-Control Matrix'!X4:X12,"X") -> 6 | H8: Not Implemented | I8: Ineffective | N8: Implemented
A9: CTRL-0018 | B9: Drift Detection | C9: Deviations from the approved, declared state are detected and alerted. | D9: Detective | E9: Automated | F9: =IF(COUNTIF('Risk-Control Matrix'!Y4:Y12,"X")=0,"—",_xlfn.TEXTJOIN(", ",TRUE(),IF('Risk-Control Matrix'!Y4="X",RIGHT('Risk-Control Matrix'!$A$4,4),""),IF('Risk-Control Matrix'!Y5="X",RIGHT('Risk-Control Matrix'!$A$5,4),""),IF('Risk-Control Matrix'!Y6="X",RIGHT('Risk-Control Matrix'!$A$6,4),""),IF('Risk-Control Matrix'!Y7="X",RIGHT('Risk-Control Matrix'!$A$7,4),""),IF('Risk-Control Matrix'!Y8="X",RIGHT('Risk-Control Matrix'!$A$8,4),""),IF('Risk-Control Matrix'!Y9="X",RIGHT('Risk-Control Matrix'!$A$9,4),""),IF('Risk-Control Matrix'!Y10="X",RIGHT('Risk-Control Matrix'!$A$10,4),""),IF('Risk-Control Matrix'!Y11="X",RIGHT('Risk-Control Matrix'!$A$11,4),""),IF('Risk-Control Matrix'!Y12="X",RIGHT('Risk-Control Matrix'!$A$12,4),""))) -> 0008 | G9: =COUNTIF('Risk-Control Matrix'!Y4:Y12,"X") -> 1 | H9: Not Implemented | I9: Not Tested | N9: To Do
A10: CTRL-0027 | B10: Post-Commit Secrets Detection & Auto-Revocation | C10: Active background monitors continuously check code repositories for leaked secrets and automatically trigger alert/rotation sequences if an accidental merge occurs. | D10: Corrective | E10: Automated | F10: 4 | G10: 1 | H10: Not Implemented | I10: Ineffective | N10: To Do

Sheet Lifecycle Controls
A1: Lifecycle Controls — SDLC Controls
A2: CONTROL | F2: RISK COVERAGE | H2: ASSESSMENT | J2: OWNER & ACTION
A3: Control ID | B3: Control | C3: Objective / Description | D3: Control Type | E3: Control Nature | F3: Risks Mitigated | G3: # Risks | H3: Implementation Status | I3: Control Effectiveness | J3: Control Owner | K3: Evidence / Reference | L3: Action Plan / Notes | M3: Target Date | N3: Status
A4: CTRL-0017 | B4: Training | C4: Personnel receive security and process training relevant to their role. | D4: Preventive | E4: Manual | F4: =IF(COUNTIF('Risk-Control Matrix'!AA4:AA12,"X")=0,"—",_xlfn.TEXTJOIN(", ",TRUE(),IF('Risk-Control Matrix'!AA4="X",RIGHT('Risk-Control Matrix'!$A$4,4),""),IF('Risk-Control Matrix'!AA5="X",RIGHT('Risk-Control Matrix'!$A$5,4),""),IF('Risk-Control Matrix'!AA6="X",RIGHT('Risk-Control Matrix'!$A$6,4),""),IF('Risk-Control Matrix'!AA7="X",RIGHT('Risk-Control Matrix'!$A$7,4),""),IF('Risk-Control Matrix'!AA8="X",RIGHT('Risk-Control Matrix'!$A$8,4),""),IF('Risk-Control Matrix'!AA9="X",RIGHT('Risk-Control Matrix'!$A$9,4),""),IF('Risk-Control Matrix'!AA10="X",RIGHT('Risk-Control Matrix'!$A$10,4),""),IF('Risk-Control Matrix'!AA11="X",RIGHT('Risk-Control Matrix'!$A$11,4),""),IF('Risk-Control Matrix'!AA12="X",RIGHT('Risk-Control Matrix'!$A$12,4),""))) -> 0002 | G4: =COUNTIF('Risk-Control Matrix'!AA4:AA12,"X") -> 1 | H4: Not Implemented | I4: Not Tested | N4: To Do
A5: CTRL-0019 | B5: Penetration Testing | C5: Independent penetration testing periodically identifies exploitable weaknesses. | D5: Detective | E5: Hybrid | F5: =IF(COUNTIF('Risk-Control Matrix'!AB4:AB12,"X")=0,"—",_xlfn.TEXTJOIN(", ",TRUE(),IF('Risk-Control Matrix'!AB4="X",RIGHT('Risk-Control Matrix'!$A$4,4),""),IF('Risk-Control Matrix'!AB5="X",RIGHT('Risk-Control Matrix'!$A$5,4),""),IF('Risk-Control Matrix'!AB6="X",RIGHT('Risk-Control Matrix'!$A$6,4),""),IF('Risk-Control Matrix'!AB7="X",RIGHT('Risk-Control Matrix'!$A$7,4),""),IF('Risk-Control Matrix'!AB8="X",RIGHT('Risk-Control Matrix'!$A$8,4),""),IF('Risk-Control Matrix'!AB9="X",RIGHT('Risk-Control Matrix'!$A$9,4),""),IF('Risk-Control Matrix'!AB10="X",RIGHT('Risk-Control Matrix'!$A$10,4),""),IF('Risk-Control Matrix'!AB11="X",RIGHT('Risk-Control Matrix'!$A$11,4),""),IF('Risk-Control Matrix'!AB12="X",RIGHT('Risk-Control Matrix'!$A$12,4),""))) -> 0005, 0009 | G5: =COUNTIF('Risk-Control Matrix'!AB4:AB12,"X") -> 2 | H5: Not Implemented | I5: Effective | N5: To Do
A6: CTRL-0011 | B6: Service Ownership | C6: Every service has a defined owner accountable for its security and operation. | D6: Preventive | E6: Manual | F6: =IF(COUNTIF('Risk-Control Matrix'!AC4:AC12,"X")=0,"—",_xlfn.TEXTJOIN(", ",TRUE(),IF('Risk-Control Matrix'!AC4="X",RIGHT('Risk-Control Matrix'!$A$4,4),""),IF('Risk-Control Matrix'!AC5="X",RIGHT('Risk-Control Matrix'!$A$5,4),""),IF('Risk-Control Matrix'!AC6="X",RIGHT('Risk-Control Matrix'!$A$6,4),""),IF('Risk-Control Matrix'!AC7="X",RIGHT('Risk-Control Matrix'!$A$7,4),""),IF('Risk-Control Matrix'!AC8="X",RIGHT('Risk-Control Matrix'!$A$8,4),""),IF('Risk-Control Matrix'!AC9="X",RIGHT('Risk-Control Matrix'!$A$9,4),""),IF('Risk-Control Matrix'!AC10="X",RIGHT('Risk-Control Matrix'!$A$10,4),""),IF('Risk-Control Matrix'!AC11="X",RIGHT('Risk-Control Matrix'!$A$11,4),""),IF('Risk-Control Matrix'!AC12="X",RIGHT('Risk-Control Matrix'!$A$12,4),""))) -> — | G6: =COUNTIF('Risk-Control Matrix'!AC4:AC12,"X") -> 0 | H6: Not Implemented | I6: Not Tested | N6: To Do
A7: CTRL-0028 | B7: Continuous Threat Modeling & Architecture Review | C7: For major releases or structural API changes, a formal threat-modeling exercise (e.g., STRIDE) must be documented and approved before engineering work begins. | D7: Preventive | E7: Manual | F7: 6 | G7: 1 | H7: Not Implemented | I7: Effective | N7: To Do
A8: CTRL-0029 | B8: GenAI Code Assistance Guardrails | C8: Ensure code generated by AI assistants (GitHub Copilot, Cursor) passes identical SAST/SCA gates as human code; policies prohibit pasting sensitive customer data or credentials into external LLMs. | D8: Preventive | E8: Manual | F8: 6 | G8: 1 | H8: Implemented | I8: Partially Effective | N8: To Do

Sheet Scoring Legend
B2: Scoring Legend & Risk Heat Map
B4: Likelihood (L) | C4: Description | E4: Impact (I) | F4: Description
B5: 1 – Rare | C5: Very unlikely within the period | E5: 1 – Insignificant | F5: No real security/data impact
B6: 2 – Unlikely | C6: Could occur but not expected | E6: 2 – Minor | F6: Limited, contained impact
B7: 3 – Possible | C7: Might occur at some point | E7: 3 – Moderate | F7: Some data/service disruption
B8: 4 – Likely | C8: Will probably occur in most cases | E8: 4 – Major | F8: Significant breach or outage
B9: 5 – Almost certain | C9: Expected / already occurring | E9: 5 – Severe | F9: Critical breach / penalty
B12: Risk Score = Likelihood × Impact
B13: I → / L ↓ | C13: 1 | D13: 2 | E13: 3 | F13: 4 | G13: 5
B14: 5 | C14: 5 | D14: 10 | E14: 15 | F14: 20 | G14: 25
